<?xml version="1.0" ?>
<!-- =================================================================================== -->
<!-- |    This document was autogenerated by xacro from /home/dyros/catkin_ws/src/posco_env_description/robots/posco_env.urdf.xacro | -->
<!-- |    EDITING THIS FILE BY HAND IS NOT RECOMMENDED                                 | -->
<!-- =================================================================================== -->
<robot name="panda">
    <!-- box shaped table as base for the 3 Pandas -->
    <link name="base">
        <visual>
            <origin rpy="0 0 0" xyz="0.4 0 0.5" />
            <geometry>
                <box size="2.7 1.2 1" />
            </geometry>
            <material name="White">
                <color rgba="1.0 1.0 1.0 1.0" />
            </material>
        </visual>
        <collision>
            <origin rpy="0 0 0  " xyz="0.4 0 0.5" />
            <geometry>
                <box size="2.7 1.2 1" />
            </geometry>
        </collision>
        <inertial>
            <mass value="0.1" />
            <origin xyz="0 0 0" rpy="0 0 0" />
            <inertia ixx="0.03" iyy="0.03" izz="0.03" ixy="0.0" ixz="0.0" iyz="0.0" />
        </inertial>
    </link>
    <joint name="base_column_1" type="fixed">
        <parent link="base" />
        <child link="column_1" />
        <origin rpy="0 0 0" xyz="0 0 0" />
    </joint>
    <link name="column_1">
        <visual>
            <origin rpy="0 0 0" xyz="1.61 0.525 1.85" />
            <geometry>
                <box size="0.13 0.13 1.6" />
            </geometry>
            <material name="color">
                <color rgba="1.0 1.0 1.0 1.0" />
            </material>
        </visual>
        <collision>
            <origin rpy="0 0 0" xyz="1.61 0.525 1.85" />
            <geometry>
                <box size="0.13 0.13 1.6" />
            </geometry>
        </collision>
        <inertial>
            <mass value="0.1" />
            <origin xyz="0 0 0" rpy="0 0 0" />
            <inertia ixx="0.03" iyy="0.03" izz="0.03" ixy="0.0" ixz="0.0" iyz="0.0" />
        </inertial>
    </link>
    <joint name="base_column_2" type="fixed">
        <parent link="base" />
        <child link="column_2" />
        <origin rpy="0 0 0" xyz="0 0 0" />
    </joint>
    <link name="column_2">
        <visual>
            <origin rpy="0 0 0" xyz="1.61 -0.525 1.85" />
            <geometry>
                <box size="0.13 0.13 1.6" />
            </geometry>
            <material name="color">
                <color rgba="1.0 1.0 1.0 1.0" />
            </material>
        </visual>
        <collision>
            <origin rpy="0 0 0" xyz="1.61 -0.525 1.85" />
            <geometry>
                <box size="0.13 0.13 1.6" />
            </geometry>
        </collision>
        <inertial>
            <mass value="0.1" />
            <origin xyz="0 0 0" rpy="0 0 0" />
            <inertia ixx="0.03" iyy="0.03" izz="0.03" ixy="0.0" ixz="0.0" iyz="0.0" />
        </inertial>
    </link>
    <joint name="base_column_3" type="fixed">
        <parent link="base" />
        <child link="column_3" />
        <origin rpy="0 0 0" xyz="0 0 0" />
    </joint>
    <link name="column_3">
        <visual>
            <origin rpy="0 0 0" xyz="-0.575 -0.525 1.85" />
            <geometry>
                <box size="0.13 0.13 1.6" />
            </geometry>
            <material name="color">
                <color rgba="1.0 1.0 1.0 1.0" />
            </material>
        </visual>
        <collision>
            <origin rpy="0 0 0" xyz="-0.575 -0.525 1.85" />
            <geometry>
                <box size="0.13 0.13 1.6" />
            </geometry>
        </collision>
        <inertial>
            <mass value="0.1" />
            <origin xyz="0 0 0" rpy="0 0 0" />
            <inertia ixx="0.03" iyy="0.03" izz="0.03" ixy="0.0" ixz="0.0" iyz="0.0" />
        </inertial>
    </link>
    <joint name="base_column_4" type="fixed">
        <parent link="base" />
        <child link="column_4" />
        <origin rpy="0 0 0" xyz="0 0 0" />
    </joint>
    <link name="column_4">
        <visual>
            <origin rpy="0 0 0" xyz="-0.575 0.525 1.85" />
            <geometry>
                <box size="0.13 0.13 1.6" />
            </geometry>
            <material name="color">
                <color rgba="1.0 1.0 1.0 1.0" />
            </material>
        </visual>
        <collision>
            <origin rpy="0 0 0" xyz="-0.575 0.525 1.85" />
            <geometry>
                <box size="0.13 0.13 1.6" />
            </geometry>
        </collision>
        <inertial>
            <mass value="0.1" />
            <origin xyz="0 0 0" rpy="0 0 0" />
            <inertia ixx="0.03" iyy="0.03" izz="0.03" ixy="0.0" ixz="0.0" iyz="0.0" />
        </inertial>
    </link>
    <joint name="base_sub_table_1" type="fixed">
        <parent link="base" />
        <child link="sub_table_1" />
        <origin rpy="0 0 0" xyz="0 0 0" />
    </joint>
    <link name="sub_table_1">
        <visual>
            <origin rpy="0 0 0" xyz="0.69 -0.04 1.0826" />
            <geometry>
                <box size="0.37 0.22 0.165" />
            </geometry>
            <material name="color">
                <color rgba="0.5 0.5 0.5 1.0" />
            </material>
        </visual>
        <collision>
            <origin rpy="0 0 0" xyz="0.69 -0.04 1.0826" />
            <geometry>
                <box size="0.37 0.22 0.165" />
            </geometry>
        </collision>
        <inertial>
            <mass value="0.1" />
            <origin xyz="0 0 0" rpy="0 0 0" />
            <inertia ixx="0.03" iyy="0.03" izz="0.03" ixy="0.0" ixz="0.0" iyz="0.0" />
        </inertial>
    </link>
    <joint name="base_sub_table_2" type="fixed">
        <parent link="base" />
        <child link="sub_table_2" />
        <origin rpy="0 0 0" xyz="0 0 0" />
    </joint>
    <link name="sub_table_2">
        <visual>
            <origin rpy="0 0 0" xyz="0.465 -0.505 1.0826" />
            <geometry>
                <box size="0.22 0.17 0.165" />
            </geometry>
            <material name="color">
                <color rgba="0.5 0.5 0.5 1.0" />
            </material>
        </visual>
        <collision>
            <origin rpy="0 0 0" xyz="0.465 -0.505 1.0826" />
            <geometry>
                <box size="0.22 0.17 0.165" />
            </geometry>
        </collision>
        <inertial>
            <mass value="0.1" />
            <origin xyz="0 0 0" rpy="0 0 0" />
            <inertia ixx="0.03" iyy="0.03" izz="0.03" ixy="0.0" ixz="0.0" iyz="0.0" />
        </inertial>
    </link>
    <joint name="base_sub_table_3" type="fixed">
        <parent link="base" />
        <child link="sub_table_3" />
        <origin rpy="0 0 0" xyz="0 0 0" />
    </joint>
    <link name="sub_table_3">
        <visual>
            <origin rpy="0 0 0" xyz="0.595 0.355 1.0826" />
            <geometry>
                <box size="0.17 0.22 0.165" />
            </geometry>
            <material name="color">
                <color rgba="0.5 0.5 0.5 1.0" />
            </material>
        </visual>
        <collision>
            <origin rpy="0 0 0" xyz="0.595 0.355 1.0826" />
            <geometry>
                <box size="0.17 0.22 0.165" />
            </geometry>
        </collision>
        <inertial>
            <mass value="0.1" />
            <origin xyz="0 0 0" rpy="0 0 0" />
            <inertia ixx="0.03" iyy="0.03" izz="0.03" ixy="0.0" ixz="0.0" iyz="0.0" />
        </inertial>
    </link>
    <joint name="base_sub_table_4" type="fixed">
        <parent link="base" />
        <child link="sub_table_4" />
        <origin rpy="0 0 0" xyz="0 0 0" />
    </joint>
    <link name="sub_table_4">
        <visual>
            <origin rpy="0 0 0" xyz="0.42 0.1 1.0826" />
            <geometry>
                <box size="0.22 0.22 0.165" />
            </geometry>
            <material name="color">
                <color rgba="0.5 0.5 0.5 1.0" />
            </material>
        </visual>
        <collision>
            <origin rpy="0 0 0" xyz="0.42 0.1 1.0826" />
            <geometry>
                <box size="0.22 0.22 0.165" />
            </geometry>
        </collision>
        <inertial>
            <mass value="0.1" />
            <origin xyz="0 0 0" rpy="0 0 0" />
            <inertia ixx="0.03" iyy="0.03" izz="0.03" ixy="0.0" ixz="0.0" iyz="0.0" />
        </inertial>
    </link>
    <joint name="panda_left_joint_base" type="fixed">
        <parent link="base" />
        <child link="panda_left_link0" />
        <origin rpy="0 0 0" xyz="0 0.3 1.006" />
    </joint>
    <link name="panda_left_link0">
        <visual>
            <geometry>
                <mesh filename="package://franka_description/meshes/visual/link0.dae" />
            </geometry>
        </visual>
        <collision>
            <!---->
            <origin rpy="0 1.5707963267948966 0" xyz="-0.075 0 0.06" />
            <geometry>
                <cylinder length="0.03" radius="0.06999999999999999" />
            </geometry>
        </collision>
        <collision>
            <!--base-->
            <origin rpy="0 0 0" xyz="-0.06 0 0.05" />
            <geometry>
                <box size="0.22 0.19 0.11" />
            </geometry>
        </collision>
        <collision>
            <!--base+front-->
            <origin rpy="0 0 0" xyz="0.02 0 0.03" />
            <geometry>
                <cylinder length="0.06" radius="0.06999999999999999" />
            </geometry>
        </collision>
        <collision>
            <!--base+cable-->
            <origin rpy="0 0 0" xyz="-0.09 -0.075 0.05" />
            <geometry>
                <box size="0.16 0.16 0.11" />
            </geometry>
        </collision>
        <collision>
            <!---->
            <origin rpy="0 0 0" xyz="-0.06 0 0.06" />
            <geometry>
                <sphere radius="0.06999999999999999" />
            </geometry>
        </collision>
        <collision>
            <!---->
            <origin rpy="0 0 0" xyz="-0.09 0 0.06" />
            <geometry>
                <sphere radius="0.06999999999999999" />
            </geometry>
        </collision>
        <inertial>
            <mass value="0.1" />
            <origin xyz="0 0 0" rpy="0 0 0" />
            <inertia ixx="0.03" iyy="0.03" izz="0.03" ixy="0.0" ixz="0.0" iyz="0.0" />
        </inertial>
    </link>
    <link name="panda_left_link1">
        <visual>
            <geometry>
                <mesh filename="package://franka_description/meshes/visual/link1.dae" />
            </geometry>
        </visual>
        <collision>
            <!---->
            <origin rpy="0 0 0" xyz="0 0 -0.1915" />
            <geometry>
                <cylinder length="0.2830" radius="0.06999999999999999" />
            </geometry>
        </collision>
        <collision>
            <!---->
            <origin rpy="0 0 0" xyz="0 0 -0.333" />
            <geometry>
                <sphere radius="0.06999999999999999" />
            </geometry>
        </collision>
        <collision>
            <!---->
            <origin rpy="0 0 0" xyz="0 0 -0.05" />
            <geometry>
                <sphere radius="0.06999999999999999" />
            </geometry>
        </collision>
        <collision>
            <!---->
            <origin rpy="0.5235987755982988 0 0" xyz="0 -0.05 -0.05" />
            <geometry>
                <cylinder length="0.12" radius="0.065" />
            </geometry>
        </collision>
        <inertial>
            <mass value="0.1" />
            <origin xyz="0 0 0" rpy="0 0 0" />
            <inertia ixx="0.03" iyy="0.03" izz="0.03" ixy="0.0" ixz="0.0" iyz="0.0" />
        </inertial>
    </link>
    <link name="panda_left_link1_augmented" />
    <joint name="panda_left_joint1_augmented" type="fixed">
        <origin rpy="0.00148667086907321 0 0" xyz="0.000474560429981023 0 0" />
        <parent link="panda_left_link0" />
        <child link="panda_left_link1_augmented" />
    </joint>
    <joint name="panda_left_joint1" type="revolute">
        <safety_controller k_position="100.0" k_velocity="40.0" soft_lower_limit="-2.8973" soft_upper_limit="2.8973" />
        <origin rpy="0 0 -0.00304883355188383" xyz="0 0 0.3334831666821653" />
        <parent link="panda_left_link1_augmented" />
        <child link="panda_left_link1" />
        <axis xyz="0 0 1" />
        <limit effort="87" lower="-2.8973" upper="2.8973" velocity="2.1750" />
    </joint>
    <link name="panda_left_link2">
        <visual>
            <geometry>
                <mesh filename="package://franka_description/meshes/visual/link2.dae" />
            </geometry>
        </visual>
        <collision>
            <!---->
            <origin rpy="2.1816615649929116 0 0" xyz="0 -0.05 0.05" />
            <geometry>
                <cylinder length="0.12" radius="0.065" />
            </geometry>
        </collision>
        <collision>
            <!---->
            <origin rpy="0 0 0" xyz="0 0 0" />
            <geometry>
                <cylinder length="0.12" radius="0.06999999999999999" />
            </geometry>
        </collision>
        <collision>
            <!---->
            <origin rpy="0 0 0" xyz="0 0 -0.08" />
            <geometry>
                <sphere radius="0.06999999999999999" />
            </geometry>
        </collision>
        <collision>
            <!---->
            <origin rpy="0 0 0" xyz="0 0 0.08" />
            <geometry>
                <sphere radius="0.06999999999999999" />
            </geometry>
        </collision>
        <inertial>
            <mass value="0.1" />
            <origin xyz="0 0 0" rpy="0 0 0" />
            <inertia ixx="0.03" iyy="0.03" izz="0.03" ixy="0.0" ixz="0.0" iyz="0.0" />
        </inertial>
    </link>
    <link name="panda_left_link2_augmented" />
    <joint name="panda_left_joint2_augmented" type="fixed">
        <origin rpy="-1.5665806554334523 0 0" xyz="-3.69828865924539e-05 0 0" />
        <parent link="panda_left_link1" />
        <child link="panda_left_link2_augmented" />
    </joint>
    <joint name="panda_left_joint2" type="revolute">
        <safety_controller k_position="100.0" k_velocity="40.0" soft_lower_limit="-1.7628" soft_upper_limit="1.7628" />
        <origin rpy="0 0 -0.00812428761844092" xyz="0 0 -0.000288069909956647" />
        <parent link="panda_left_link2_augmented" />
        <child link="panda_left_link2" />
        <axis xyz="0 0 1" />
        <limit effort="87" lower="-1.7628" upper="1.7628" velocity="2.1750" />
    </joint>
    <link name="panda_left_link3">
        <visual>
            <geometry>
                <mesh filename="package://franka_description/meshes/visual/link3.dae" />
            </geometry>
        </visual>
        <collision>
            <!--link3 body-->
            <origin rpy="0 0 0" xyz="0 0 -0.145" />
            <geometry>
                <cylinder length="0.15" radius="0.06999999999999999" />
            </geometry>
        </collision>
        <collision>
            <!---->
            <origin rpy="0 0 0" xyz="0 0 -0.22" />
            <geometry>
                <sphere radius="0.06999999999999999" />
            </geometry>
        </collision>
        <collision>
            <!---->
            <origin rpy="0 0 0" xyz="0 0 -0.07" />
            <geometry>
                <sphere radius="0.06999999999999999" />
            </geometry>
        </collision>
        <inertial>
            <mass value="0.1" />
            <origin xyz="0 0 0" rpy="0 0 0" />
            <inertia ixx="0.03" iyy="0.03" izz="0.03" ixy="0.0" ixz="0.0" iyz="0.0" />
        </inertial>
    </link>
    <link name="panda_left_link3_augmented" />
    <joint name="panda_left_joint3_augmented" type="fixed">
        <origin rpy="1.5677488342757828 0 0" xyz="-0.000154357131719552 0 0" />
        <parent link="panda_left_link2" />
        <child link="panda_left_link3_augmented" />
    </joint>
    <joint name="panda_left_joint3" type="revolute">
        <safety_controller k_position="100.0" k_velocity="40.0" soft_lower_limit="-2.8973" soft_upper_limit="2.8973" />
        <origin rpy="0 0 0.00031894496234845" xyz="0 0 0.3149078635222183" />
        <parent link="panda_left_link3_augmented" />
        <child link="panda_left_link3" />
        <axis xyz="0 0 1" />
        <limit effort="87" lower="-2.8973" upper="2.8973" velocity="2.1750" />
    </joint>
    <link name="panda_left_link4">
        <visual>
            <geometry>
                <mesh filename="package://franka_description/meshes/visual/link4.dae" />
            </geometry>
        </visual>
        <collision>
            <!--link4 body-->
            <origin rpy="0 0 0" xyz="0 0 0" />
            <geometry>
                <cylinder length="0.12" radius="0.06999999999999999" />
            </geometry>
        </collision>
        <collision>
            <!---->
            <origin rpy="0 0 0" xyz="0 0 0.06" />
            <geometry>
                <sphere radius="0.06999999999999999" />
            </geometry>
        </collision>
        <collision>
            <!---->
            <origin rpy="0 0 0" xyz="-0.01 0.01 0.07" />
            <geometry>
                <cylinder length="0.02" radius="0.06999999999999999" />
            </geometry>
        </collision>
        <collision>
            <!---->
            <origin rpy="0 0 0" xyz="0.01 -0.01 -0.07" />
            <geometry>
                <cylinder length="0.02" radius="0.06999999999999999" />
            </geometry>
        </collision>
        <collision>
            <!---->
            <origin rpy="0 0 0" xyz="0 0 -0.06" />
            <geometry>
                <sphere radius="0.06999999999999999" />
            </geometry>
        </collision>
        <inertial>
            <mass value="0.1" />
            <origin xyz="0 0 0" rpy="0 0 0" />
            <inertia ixx="0.03" iyy="0.03" izz="0.03" ixy="0.0" ixz="0.0" iyz="0.0" />
        </inertial>
    </link>
    <link name="panda_left_link4_augmented" />
    <joint name="panda_left_joint4_augmented" type="fixed">
        <origin rpy="1.5725650064897585 0 0" xyz="0.08238239959512977 0 0" />
        <parent link="panda_left_link3" />
        <child link="panda_left_link4_augmented" />
    </joint>
    <joint name="panda_left_joint4" type="revolute">
        <safety_controller k_position="100.0" k_velocity="40.0" soft_lower_limit="-3.0718" soft_upper_limit="-0.0698" />
        <origin rpy="0 0 -0.00571261767823764" xyz="0 0 0.000712982958085577" />
        <parent link="panda_left_link4_augmented" />
        <child link="panda_left_link4" />
        <axis xyz="0 0 1" />
        <limit effort="87" lower="-3.0718" upper="-0.0698" velocity="2.1750" />
    </joint>
    <link name="panda_left_link5">
        <visual>
            <geometry>
                <mesh filename="package://franka_description/meshes/visual/link5.dae" />
            </geometry>
        </visual>
        <collision>
            <!---->
            <origin rpy="0 0 0" xyz="0 0 -0.26" />
            <geometry>
                <cylinder length="0.1" radius="0.06999999999999999" />
            </geometry>
        </collision>
        <collision>
            <!--almost link 4-->
            <origin rpy="0 0 0" xyz="0 0 -0.32" />
            <geometry>
                <sphere radius="0.06999999999999999" />
            </geometry>
        </collision>
        <collision>
            <!---->
            <origin rpy="0 0 0" xyz="0 0 -0.22" />
            <geometry>
                <sphere radius="0.06999999999999999" />
            </geometry>
        </collision>
        <collision>
            <!--link5 long body part-->
            <origin rpy="-0.13962634015954636 0 0" xyz="0 0.08 -0.12" />
            <geometry>
                <cylinder length="0.17" radius="0.045000000000000005" />
            </geometry>
        </collision>
        <collision>
            <!--curve part-->
            <origin rpy="0 0 0" xyz="0 0.085 0" />
            <geometry>
                <sphere radius="0.06999999999999999" />
            </geometry>
        </collision>
        <collision>
            <!---->
            <origin rpy="0 0 0" xyz="0 0.05 -0.19" />
            <geometry>
                <sphere radius="0.060000000000000005" />
            </geometry>
        </collision>
        <inertial>
            <mass value="0.1" />
            <origin xyz="0 0 0" rpy="0 0 0" />
            <inertia ixx="0.03" iyy="0.03" izz="0.03" ixy="0.0" ixz="0.0" iyz="0.0" />
        </inertial>
    </link>
    <link name="panda_left_link5_augmented" />
    <joint name="panda_left_joint5_augmented" type="fixed">
        <origin rpy="-1.5695590890723086 0 0" xyz="-0.08308993701921134 0 0" />
        <parent link="panda_left_link4" />
        <child link="panda_left_link5_augmented" />
    </joint>
    <joint name="panda_left_joint5" type="revolute">
        <safety_controller k_position="100.0" k_velocity="40.0" soft_lower_limit="-2.8973" soft_upper_limit="2.8973" />
        <origin rpy="0 0 0.00939394386245098" xyz="0 0 0.3836733503547864" />
        <parent link="panda_left_link5_augmented" />
        <child link="panda_left_link5" />
        <axis xyz="0 0 1" />
        <limit effort="12" lower="-2.8973" upper="2.8973" velocity="2.6100" />
    </joint>
    <link name="panda_left_link6">
        <visual>
            <geometry>
                <mesh filename="package://franka_description/meshes/visual/link6.dae" />
            </geometry>
        </visual>
        <collision>
            <!---->
            <origin rpy="0 0 0" xyz="0 0 -0.03" />
            <geometry>
                <cylinder length="0.08" radius="0.06999999999999999" />
            </geometry>
        </collision>
        <collision>
            <!---->
            <origin rpy="0 1.5707963267948966 0" xyz="0.02 0 0.01" />
            <geometry>
                <cylinder length="0.07" radius="0.06999999999999999" />
            </geometry>
        </collision>
        <collision>
            <!--curve part-->
            <origin rpy="0 0 0" xyz="0 0 0.01" />
            <geometry>
                <sphere radius="0.06999999999999999" />
            </geometry>
        </collision>
        <collision>
            <!--link6and5 connection part-->
            <origin rpy="0 0 0" xyz="0 0 -0.08" />
            <geometry>
                <sphere radius="0.061" />
            </geometry>
        </collision>
        <inertial>
            <mass value="0.1" />
            <origin xyz="0 0 0" rpy="0 0 0" />
            <inertia ixx="0.03" iyy="0.03" izz="0.03" ixy="0.0" ixz="0.0" iyz="0.0" />
        </inertial>
    </link>
    <link name="panda_left_link6_augmented" />
    <joint name="panda_left_joint6_augmented" type="fixed">
        <origin rpy="1.5655031173446372 0 0" xyz="-0.000433705606644922 0 0" />
        <parent link="panda_left_link5" />
        <child link="panda_left_link6_augmented" />
    </joint>
    <joint name="panda_left_joint6" type="revolute">
        <safety_controller k_position="100.0" k_velocity="40.0" soft_lower_limit="-0.0175" soft_upper_limit="3.7525" />
        <origin rpy="0 0 -0.0156742348127345" xyz="0 0 -0.000293762477507038" />
        <parent link="panda_left_link6_augmented" />
        <child link="panda_left_link6" />
        <axis xyz="0 0 1" />
        <limit effort="12" lower="-0.0175" upper="3.7525" velocity="2.6100" />
        <!-- <limit effort="12" lower="0.75" upper="3.7525" velocity="2.6100"/> -->
    </joint>
    <link name="panda_left_link7">
        <visual>
            <geometry>
                <mesh filename="package://franka_description/meshes/visual/link7.dae" />
            </geometry>
        </visual>
        <collision>
            <!--link7's body-->
            <origin rpy="0 0 0" xyz="0 0 0.01" />
            <geometry>
                <cylinder length="0.14" radius="0.055" />
            </geometry>
        </collision>
        <collision>
            <!--link7and8 connection part-->
            <origin rpy="0 0 0" xyz="0 0 0.08" />
            <geometry>
                <sphere radius="0.05" />
            </geometry>
        </collision>
        <collision>
            <!--button part-->
            <origin rpy="0 0 0" xyz="0 0 -0.06" />
            <geometry>
                <sphere radius="0.055" />
            </geometry>
        </collision>
        <inertial>
            <mass value="0.1" />
            <origin xyz="0 0 0" rpy="0 0 0" />
            <inertia ixx="0.03" iyy="0.03" izz="0.03" ixy="0.0" ixz="0.0" iyz="0.0" />
        </inertial>
    </link>
    <link name="panda_left_link7_augmented" />
    <joint name="panda_left_joint7_augmented" type="fixed">
        <origin rpy="1.5719283512181828 0 0" xyz="0.08741018468457062 0 0" />
        <parent link="panda_left_link6" />
        <child link="panda_left_link7_augmented" />
    </joint>
    <joint name="panda_left_joint7" type="revolute">
        <safety_controller k_position="100.0" k_velocity="40.0" soft_lower_limit="-2.8973" soft_upper_limit="2.8973" />
        <origin rpy="0 0 0.0291501803388187" xyz="0 0 6.2389274666678e-05" />
        <parent link="panda_left_link7_augmented" />
        <child link="panda_left_link7" />
        <axis xyz="0 0 1" />
        <limit effort="12" lower="-2.8973" upper="2.8973" velocity="2.6100" />
    </joint>
    <link name="panda_left_link8">
        <collision>
            <!--button part-->
            <origin rpy="0 0 0.7853981633974483" xyz="0.04 0.04 -0.03" />
            <geometry>
                <box size="0.07100000000000001 0.07100000000000001 0.021" />
            </geometry>
        </collision>
        <collision>
            <!--rotate part-->
            <origin rpy="0 0 0" xyz="0 0 -0.028" />
            <geometry>
                <cylinder length="0.05" radius="0.051000000000000004" />
            </geometry>
        </collision>
        <inertial>
            <mass value="0.1" />
            <origin xyz="0 0 0" rpy="0 0 0" />
            <inertia ixx="0.03" iyy="0.03" izz="0.03" ixy="0.0" ixz="0.0" iyz="0.0" />
        </inertial>
    </link>
    <joint name="panda_left_joint8" type="fixed">
        <origin rpy="0 0 0" xyz="0 0 0.107" />
        <parent link="panda_left_link7" />
        <child link="panda_left_link8" />
    </joint>
    <joint name="panda_left_hand_joint" type="fixed">
        <parent link="panda_left_link8" />
        <child link="panda_left_hand" />
        <origin rpy="0 0 -0.7853981633974483" xyz="0 0 0" />
    </joint>
    <link name="panda_left_hand">
        <visual>
            <geometry>
                <mesh filename="package://franka_description/meshes/visual/hand.dae" />
            </geometry>
        </visual>
        <collision>
            <origin rpy="0 0 0" xyz="0 0 0.025" />
            <geometry>
                <box size="0.045 0.21 0.09" />
            </geometry>
        </collision>
        <collision>
            <origin rpy="0 0 0" xyz="0.0 0 0.025" />
            <geometry>
                <box size="0.0 0.0 0.0" />
            </geometry>
        </collision>
        <inertial>
            <mass value="0.1" />
            <origin xyz="0 0 0" rpy="0 0 0" />
            <inertia ixx="0.03" iyy="0.03" izz="0.03" ixy="0.0" ixz="0.0" iyz="0.0" />
        </inertial>
    </link>
    <link name="panda_left_leftfinger">
        <visual>
            <geometry>
                <mesh filename="package://franka_description/meshes/visual/finger.dae" />
            </geometry>
        </visual>
        <collision>
            <origin rpy="0 0 0" xyz="0 0.014 0.03" />
            <geometry>
                <box size="0.025 0.03 0.05" />
            </geometry>
        </collision>
        <inertial>
            <mass value="0.1" />
            <origin xyz="0 0 0" rpy="0 0 0" />
            <inertia ixx="0.03" iyy="0.03" izz="0.03" ixy="0.0" ixz="0.0" iyz="0.0" />
        </inertial>
    </link>
    <link name="panda_left_rightfinger">
        <visual>
            <origin rpy="0 0 3.141592653589793" xyz="0 0 0" />
            <geometry>
                <mesh filename="package://franka_description/meshes/visual/finger.dae" />
            </geometry>
        </visual>
        <collision>
            <origin rpy="0 0 0" xyz="0 -0.014 0.03" />
            <geometry>
                <box size="0.025 0.03 0.05" />
            </geometry>
        </collision>
        <inertial>
            <mass value="0.1" />
            <origin xyz="0 0 0" rpy="0 0 0" />
            <inertia ixx="0.03" iyy="0.03" izz="0.03" ixy="0.0" ixz="0.0" iyz="0.0" />
        </inertial>
    </link>
    <joint name="panda_left_finger_joint1" type="prismatic">
        <parent link="panda_left_hand" />
        <child link="panda_left_leftfinger" />
        <origin rpy="0 0 0" xyz="0 0 0.0584" />
        <axis xyz="0 1 0" />
        <limit effort="20" lower="0.0" upper="0.04" velocity="0.2" />
    </joint>
    <joint name="panda_left_finger_joint2" type="prismatic">
        <parent link="panda_left_hand" />
        <child link="panda_left_rightfinger" />
        <origin rpy="0 0 0" xyz="0 0 0.0584" />
        <axis xyz="0 -1 0" />
        <limit effort="20" lower="0.0" upper="0.04" velocity="0.2" />
        <mimic joint="panda_left_finger_joint1" />
    </joint>
    <joint name="panda_right_joint_base" type="fixed">
        <parent link="base" />
        <child link="panda_right_link0" />
        <origin rpy="0 0 0" xyz="0 -0.3 1.006" />
    </joint>
    <link name="panda_right_link0">
        <visual>
            <geometry>
                <mesh filename="package://franka_description/meshes/visual/link0.dae" />
            </geometry>
        </visual>
        <collision>
            <!---->
            <origin rpy="0 1.5707963267948966 0" xyz="-0.075 0 0.06" />
            <geometry>
                <cylinder length="0.03" radius="0.06999999999999999" />
            </geometry>
        </collision>
        <collision>
            <!--base-->
            <origin rpy="0 0 0" xyz="-0.06 0 0.05" />
            <geometry>
                <box size="0.22 0.19 0.11" />
            </geometry>
        </collision>
        <collision>
            <!--base+front-->
            <origin rpy="0 0 0" xyz="0.02 0 0.03" />
            <geometry>
                <cylinder length="0.06" radius="0.06999999999999999" />
            </geometry>
        </collision>
        <collision>
            <!--base+cable-->
            <origin rpy="0 0 0" xyz="-0.09 -0.22499999999999998 0.05" />
            <geometry>
                <box size="0.16 0.31 0.11" />
            </geometry>
        </collision>
        <collision>
            <!---->
            <origin rpy="0 0 0" xyz="-0.06 0 0.06" />
            <geometry>
                <sphere radius="0.06999999999999999" />
            </geometry>
        </collision>
        <collision>
            <!---->
            <origin rpy="0 0 0" xyz="-0.09 0 0.06" />
            <geometry>
                <sphere radius="0.06999999999999999" />
            </geometry>
        </collision>
        <inertial>
            <mass value="0.1" />
            <origin xyz="0 0 0" rpy="0 0 0" />
            <inertia ixx="0.03" iyy="0.03" izz="0.03" ixy="0.0" ixz="0.0" iyz="0.0" />
        </inertial>
    </link>
    <link name="panda_right_link1">
        <visual>
            <geometry>
                <mesh filename="package://franka_description/meshes/visual/link1.dae" />
            </geometry>
        </visual>
        <collision>
            <!---->
            <origin rpy="0 0 0" xyz="0 0 -0.1915" />
            <geometry>
                <cylinder length="0.2830" radius="0.06999999999999999" />
            </geometry>
        </collision>
        <collision>
            <!---->
            <origin rpy="0 0 0" xyz="0 0 -0.333" />
            <geometry>
                <sphere radius="0.06999999999999999" />
            </geometry>
        </collision>
        <collision>
            <!---->
            <origin rpy="0 0 0" xyz="0 0 -0.05" />
            <geometry>
                <sphere radius="0.06999999999999999" />
            </geometry>
        </collision>
        <collision>
            <!---->
            <origin rpy="0.5235987755982988 0 0" xyz="0 -0.05 -0.05" />
            <geometry>
                <cylinder length="0.12" radius="0.065" />
            </geometry>
        </collision>
        <inertial>
            <mass value="0.1" />
            <origin xyz="0 0 0" rpy="0 0 0" />
            <inertia ixx="0.03" iyy="0.03" izz="0.03" ixy="0.0" ixz="0.0" iyz="0.0" />
        </inertial>
    </link>
    <link name="panda_right_link1_augmented" />
    <joint name="panda_right_joint1_augmented" type="fixed">
        <origin rpy="-0.00183369895482027 0 0" xyz="-0.00153055068483914 0 0" />
        <parent link="panda_right_link0" />
        <child link="panda_right_link1_augmented" />
    </joint>
    <joint name="panda_right_joint1" type="revolute">
        <safety_controller k_position="100.0" k_velocity="40.0" soft_lower_limit="-2.8973" soft_upper_limit="2.8973" />
        <origin rpy="0 0 -0.00374187596482555" xyz="0 0 0.3322275140809909" />
        <parent link="panda_right_link1_augmented" />
        <child link="panda_right_link1" />
        <axis xyz="0 0 1" />
        <limit effort="87" lower="-2.8973" upper="2.8973" velocity="2.1750" />
    </joint>
    <link name="panda_right_link2">
        <visual>
            <geometry>
                <mesh filename="package://franka_description/meshes/visual/link2.dae" />
            </geometry>
        </visual>
        <collision>
            <!---->
            <origin rpy="2.1816615649929116 0 0" xyz="0 -0.05 0.05" />
            <geometry>
                <cylinder length="0.12" radius="0.065" />
            </geometry>
        </collision>
        <collision>
            <!---->
            <origin rpy="0 0 0" xyz="0 0 0" />
            <geometry>
                <cylinder length="0.12" radius="0.06999999999999999" />
            </geometry>
        </collision>
        <collision>
            <!---->
            <origin rpy="0 0 0" xyz="0 0 -0.08" />
            <geometry>
                <sphere radius="0.06999999999999999" />
            </geometry>
        </collision>
        <collision>
            <!---->
            <origin rpy="0 0 0" xyz="0 0 0.08" />
            <geometry>
                <sphere radius="0.06999999999999999" />
            </geometry>
        </collision>
        <inertial>
            <mass value="0.1" />
            <origin xyz="0 0 0" rpy="0 0 0" />
            <inertia ixx="0.03" iyy="0.03" izz="0.03" ixy="0.0" ixz="0.0" iyz="0.0" />
        </inertial>
    </link>
    <link name="panda_right_link2_augmented" />
    <joint name="panda_right_joint2_augmented" type="fixed">
        <origin rpy="-1.5678740887356988 0 0" xyz="0.000163834922530543 0 0" />
        <parent link="panda_right_link1" />
        <child link="panda_right_link2_augmented" />
    </joint>
    <joint name="panda_right_joint2" type="revolute">
        <safety_controller k_position="100.0" k_velocity="40.0" soft_lower_limit="-1.7628" soft_upper_limit="1.7628" />
        <origin rpy="0 0 -0.0041768339596184" xyz="0 0 -0.000212890734425727" />
        <parent link="panda_right_link2_augmented" />
        <child link="panda_right_link2" />
        <axis xyz="0 0 1" />
        <limit effort="87" lower="-1.7628" upper="1.7628" velocity="2.1750" />
    </joint>
    <link name="panda_right_link3">
        <visual>
            <geometry>
                <mesh filename="package://franka_description/meshes/visual/link3.dae" />
            </geometry>
        </visual>
        <collision>
            <!--link3 body-->
            <origin rpy="0 0 0" xyz="0 0 -0.145" />
            <geometry>
                <cylinder length="0.15" radius="0.06999999999999999" />
            </geometry>
        </collision>
        <collision>
            <!---->
            <origin rpy="0 0 0" xyz="0 0 -0.22" />
            <geometry>
                <sphere radius="0.06999999999999999" />
            </geometry>
        </collision>
        <collision>
            <!---->
            <origin rpy="0 0 0" xyz="0 0 -0.07" />
            <geometry>
                <sphere radius="0.06999999999999999" />
            </geometry>
        </collision>
        <inertial>
            <mass value="0.1" />
            <origin xyz="0 0 0" rpy="0 0 0" />
            <inertia ixx="0.03" iyy="0.03" izz="0.03" ixy="0.0" ixz="0.0" iyz="0.0" />
        </inertial>
    </link>
    <link name="panda_right_link3_augmented" />
    <joint name="panda_right_joint3_augmented" type="fixed">
        <origin rpy="1.5671683164886596 0 0" xyz="-2.60271767179549e-05 0 0" />
        <parent link="panda_right_link2" />
        <child link="panda_right_link3_augmented" />
    </joint>
    <joint name="panda_right_joint3" type="revolute">
        <safety_controller k_position="100.0" k_velocity="40.0" soft_lower_limit="-2.8973" soft_upper_limit="2.8973" />
        <origin rpy="0 0 0.00208915153420725" xyz="0 0 0.3149906913013996" />
        <parent link="panda_right_link3_augmented" />
        <child link="panda_right_link3" />
        <axis xyz="0 0 1" />
        <limit effort="87" lower="-2.8973" upper="2.8973" velocity="2.1750" />
    </joint>
    <link name="panda_right_link4">
        <visual>
            <geometry>
                <mesh filename="package://franka_description/meshes/visual/link4.dae" />
            </geometry>
        </visual>
        <collision>
            <!--link4 body-->
            <origin rpy="0 0 0" xyz="0 0 0" />
            <geometry>
                <cylinder length="0.12" radius="0.06999999999999999" />
            </geometry>
        </collision>
        <collision>
            <!---->
            <origin rpy="0 0 0" xyz="0 0 0.06" />
            <geometry>
                <sphere radius="0.06999999999999999" />
            </geometry>
        </collision>
        <collision>
            <!---->
            <origin rpy="0 0 0" xyz="-0.01 0.01 0.07" />
            <geometry>
                <cylinder length="0.02" radius="0.06999999999999999" />
            </geometry>
        </collision>
        <collision>
            <!---->
            <origin rpy="0 0 0" xyz="0.01 -0.01 -0.07" />
            <geometry>
                <cylinder length="0.02" radius="0.06999999999999999" />
            </geometry>
        </collision>
        <collision>
            <!---->
            <origin rpy="0 0 0" xyz="0 0 -0.06" />
            <geometry>
                <sphere radius="0.06999999999999999" />
            </geometry>
        </collision>
        <inertial>
            <mass value="0.1" />
            <origin xyz="0 0 0" rpy="0 0 0" />
            <inertia ixx="0.03" iyy="0.03" izz="0.03" ixy="0.0" ixz="0.0" iyz="0.0" />
        </inertial>
    </link>
    <link name="panda_right_link4_augmented" />
    <joint name="panda_right_joint4_augmented" type="fixed">
        <origin rpy="1.573725454778233 0 0" xyz="0.0827126348171224 0 0" />
        <parent link="panda_right_link3" />
        <child link="panda_right_link4_augmented" />
    </joint>
    <joint name="panda_right_joint4" type="revolute">
        <safety_controller k_position="100.0" k_velocity="40.0" soft_lower_limit="-3.0718" soft_upper_limit="-0.0698" />
        <origin rpy="0 0 9.81965015663654e-05" xyz="0 0 0.00108679894872676" />
        <parent link="panda_right_link4_augmented" />
        <child link="panda_right_link4" />
        <axis xyz="0 0 1" />
        <limit effort="87" lower="-3.0718" upper="-0.0698" velocity="2.1750" />
    </joint>
    <link name="panda_right_link5">
        <visual>
            <geometry>
                <mesh filename="package://franka_description/meshes/visual/link5.dae" />
            </geometry>
        </visual>
        <collision>
            <!---->
            <origin rpy="0 0 0" xyz="0 0 -0.26" />
            <geometry>
                <cylinder length="0.1" radius="0.06999999999999999" />
            </geometry>
        </collision>
        <collision>
            <!--almost link 4-->
            <origin rpy="0 0 0" xyz="0 0 -0.32" />
            <geometry>
                <sphere radius="0.06999999999999999" />
            </geometry>
        </collision>
        <collision>
            <!---->
            <origin rpy="0 0 0" xyz="0 0 -0.22" />
            <geometry>
                <sphere radius="0.06999999999999999" />
            </geometry>
        </collision>
        <collision>
            <!--link5 long body part-->
            <origin rpy="-0.13962634015954636 0 0" xyz="0 0.08 -0.12" />
            <geometry>
                <cylinder length="0.17" radius="0.045000000000000005" />
            </geometry>
        </collision>
        <collision>
            <!--curve part-->
            <origin rpy="0 0 0" xyz="0 0.085 0" />
            <geometry>
                <sphere radius="0.06999999999999999" />
            </geometry>
        </collision>
        <collision>
            <!---->
            <origin rpy="0 0 0" xyz="0 0.05 -0.19" />
            <geometry>
                <sphere radius="0.060000000000000005" />
            </geometry>
        </collision>
        <inertial>
            <mass value="0.1" />
            <origin xyz="0 0 0" rpy="0 0 0" />
            <inertia ixx="0.03" iyy="0.03" izz="0.03" ixy="0.0" ixz="0.0" iyz="0.0" />
        </inertial>
    </link>
    <link name="panda_right_link5_augmented" />
    <joint name="panda_right_joint5_augmented" type="fixed">
        <origin rpy="-1.5720200757766438 0 0" xyz="-0.08386529072609947 0 0" />
        <parent link="panda_right_link4" />
        <child link="panda_right_link5_augmented" />
    </joint>
    <joint name="panda_right_joint5" type="revolute">
        <safety_controller k_position="100.0" k_velocity="40.0" soft_lower_limit="-2.8973" soft_upper_limit="2.8973" />
        <origin rpy="0 0 0.0139799357258803" xyz="0 0 0.3839437200993644" />
        <parent link="panda_right_link5_augmented" />
        <child link="panda_right_link5" />
        <axis xyz="0 0 1" />
        <limit effort="12" lower="-2.8973" upper="2.8973" velocity="2.6100" />
    </joint>
    <link name="panda_right_link6">
        <visual>
            <geometry>
                <mesh filename="package://franka_description/meshes/visual/link6.dae" />
            </geometry>
        </visual>
        <collision>
            <!---->
            <origin rpy="0 0 0" xyz="0 0 -0.03" />
            <geometry>
                <cylinder length="0.08" radius="0.06999999999999999" />
            </geometry>
        </collision>
        <collision>
            <!---->
            <origin rpy="0 1.5707963267948966 0" xyz="0.02 0 0.01" />
            <geometry>
                <cylinder length="0.07" radius="0.06999999999999999" />
            </geometry>
        </collision>
        <collision>
            <!--curve part-->
            <origin rpy="0 0 0" xyz="0 0 0.01" />
            <geometry>
                <sphere radius="0.06999999999999999" />
            </geometry>
        </collision>
        <collision>
            <!--link6and5 connection part-->
            <origin rpy="0 0 0" xyz="0 0 -0.08" />
            <geometry>
                <sphere radius="0.061" />
            </geometry>
        </collision>
        <inertial>
            <mass value="0.1" />
            <origin xyz="0 0 0" rpy="0 0 0" />
            <inertia ixx="0.03" iyy="0.03" izz="0.03" ixy="0.0" ixz="0.0" iyz="0.0" />
        </inertial>
    </link>
    <link name="panda_right_link6_augmented" />
    <joint name="panda_right_joint6_augmented" type="fixed">
        <origin rpy="1.5681095722185878 0 0" xyz="-0.000502587880406569 0 0" />
        <parent link="panda_right_link5" />
        <child link="panda_right_link6_augmented" />
    </joint>
    <joint name="panda_right_joint6" type="revolute">
        <safety_controller k_position="100.0" k_velocity="40.0" soft_lower_limit="-0.0175" soft_upper_limit="3.7525" />
        <origin rpy="0 0 -0.0139808833528828" xyz="0 0 0.000336192838117574" />
        <parent link="panda_right_link6_augmented" />
        <child link="panda_right_link6" />
        <axis xyz="0 0 1" />
        <limit effort="12" lower="-0.0175" upper="3.7525" velocity="2.6100" />
        <!-- <limit effort="12" lower="0.75" upper="3.7525" velocity="2.6100"/> -->
    </joint>
    <link name="panda_right_link7">
        <visual>
            <geometry>
                <mesh filename="package://franka_description/meshes/visual/link7.dae" />
            </geometry>
        </visual>
        <collision>
            <!--link7's body-->
            <origin rpy="0 0 0" xyz="0 0 0.01" />
            <geometry>
                <cylinder length="0.14" radius="0.055" />
            </geometry>
        </collision>
        <collision>
            <!--link7and8 connection part-->
            <origin rpy="0 0 0" xyz="0 0 0.08" />
            <geometry>
                <sphere radius="0.05" />
            </geometry>
        </collision>
        <collision>
            <!--button part-->
            <origin rpy="0 0 0" xyz="0 0 -0.06" />
            <geometry>
                <sphere radius="0.055" />
            </geometry>
        </collision>
        <inertial>
            <mass value="0.1" />
            <origin xyz="0 0 0" rpy="0 0 0" />
            <inertia ixx="0.03" iyy="0.03" izz="0.03" ixy="0.0" ixz="0.0" iyz="0.0" />
        </inertial>
    </link>
    <link name="panda_right_link7_augmented" />
    <joint name="panda_right_joint7_augmented" type="fixed">
        <origin rpy="1.5711461021018935 0 0" xyz="0.08695352833967712 0 0" />
        <parent link="panda_right_link6" />
        <child link="panda_right_link7_augmented" />
    </joint>
    <joint name="panda_right_joint7" type="revolute">
        <safety_controller k_position="100.0" k_velocity="40.0" soft_lower_limit="-2.8973" soft_upper_limit="2.8973" />
        <origin rpy="0 0 0.00498364620994882" xyz="0 0 0.000135297170834114" />
        <parent link="panda_right_link7_augmented" />
        <child link="panda_right_link7" />
        <axis xyz="0 0 1" />
        <limit effort="12" lower="-2.8973" upper="2.8973" velocity="2.6100" />
    </joint>
    <link name="panda_right_link8">
        <collision>
            <!--button part-->
            <origin rpy="0 0 0.7853981633974483" xyz="0.04 0.04 -0.03" />
            <geometry>
                <box size="0.07100000000000001 0.07100000000000001 0.021" />
            </geometry>
        </collision>
        <collision>
            <!--rotate part-->
            <origin rpy="0 0 0" xyz="0 0 -0.028" />
            <geometry>
                <cylinder length="0.05" radius="0.051000000000000004" />
            </geometry>
        </collision>
        <inertial>
            <mass value="0.1" />
            <origin xyz="0 0 0" rpy="0 0 0" />
            <inertia ixx="0.03" iyy="0.03" izz="0.03" ixy="0.0" ixz="0.0" iyz="0.0" />
        </inertial>
    </link>
    <joint name="panda_right_joint8" type="fixed">
        <origin rpy="0 0 0" xyz="0 0 0.107" />
        <parent link="panda_right_link7" />
        <child link="panda_right_link8" />
    </joint>
    <joint name="panda_right_hand_joint" type="fixed">
        <parent link="panda_right_link8" />
        <child link="panda_right_hand" />
        <origin rpy="0 0 -0.7853981633974483" xyz="0 0 0" />
    </joint>
    <link name="panda_right_hand">
        <visual>
            <origin rpy="-1.57 0 -1.57" xyz="0 0 0" />
            <geometry>
                <mesh filename="package://assembly_env_description/meshes/gripper2_base.stl" scale="0.001 0.001 0.001" />
            </geometry>
            <material name="white">
                <color rgba="0.9 0.9 0.9 0.75" />
            </material>
        </visual>
        <collision>
            <origin rpy="0 0 0" xyz="0.017 0 0.029" />
            <geometry>
                <box size="0.125 0.21 0.06" />
            </geometry>
        </collision>
        <inertial>
            <mass value="0.55" />
            <inertia ixx="0.0014362" ixy="0.000013" ixz="-0.0000278" iyy="0.00077" iyz="-0.0000000" izz="0.001039" />
            <origin xyz="0 0 0" rpy="0 0 0" />
        </inertial>
    </link>
    <joint name="panda_right_finger_right_joint" type="prismatic">
        <parent link="panda_right_hand" />
        <child link="panda_right_finger_right_link" />
        <origin rpy="0 0 0" xyz="0 0.009 +0.0590" />
        <axis xyz="0 +1 0" />
        <limit effort="1000000" lower="-0.1" upper="0.15" velocity="1000000" />
    </joint>
    <link name="panda_right_finger_right_link">
        <visual>
            <origin rpy="-1.57 0 -1.57" xyz="0 0 0" />
            <geometry>
                <mesh filename="package://assembly_env_description/meshes/gripper2_tip.stl" scale="0.001 0.001 0.001" />
            </geometry>
            <material name="gray">
                <color rgba="0.25 0.3 0.35 0.75" />
            </material>
        </visual>
        <collision>
            <origin rpy="0 0 0" xyz="0 0 0.01" />
            <geometry>
                <box size="0.08 0.0185 0.035" />
            </geometry>
        </collision>
        <inertial>
            <mass value="0.1" />
            <origin xyz="0 0 0" rpy="0 0 0" />
            <inertia ixx="0.03" iyy="0.03" izz="0.03" ixy="0.0" ixz="0.0" iyz="0.0" />
        </inertial>
    </link>
    <joint name="panda_right_finger_left_joint" type="prismatic">
        <parent link="panda_right_hand" />
        <child link="panda_right_finger_left_link" />
        <origin rpy="0 0 0" xyz="0 -0.009 +0.0590" />
        <axis xyz="0 -1 0" />
        <limit effort="1000000" lower="-0.1" upper="0.15" velocity="1000000" />
    </joint>
    <link name="panda_right_finger_left_link">
        <visual>
            <origin rpy="-1.57 0 -1.57" xyz="0 0 0" />
            <geometry>
                <mesh filename="package://assembly_env_description/meshes/gripper2_tip.stl" scale="0.001 0.001 0.001" />
            </geometry>
            <material name="gray">
                <color rgba="0.25 0.3 0.35 0.75" />
            </material>
        </visual>
        <collision>
            <origin rpy="0 0 0" xyz="0 0 0.01" />
            <geometry>
                <box size="0.08 0.0185 0.035" />
            </geometry>
        </collision>
        <inertial>
            <mass value="0.1" />
            <origin xyz="0 0 0" rpy="0 0 0" />
            <inertia ixx="0.03" iyy="0.03" izz="0.03" ixy="0.0" ixz="0.0" iyz="0.0" />
        </inertial>
    </link>
    <!-- <xacro:hand ns="panda_right" rpy="0 0 ${-pi/4}" connected_to="panda_right_link8" /> -->
    <joint name="panda_top_joint_base" type="fixed">
        <parent link="base" />
        <child link="panda_top_link0" />
        <origin rpy="0 0 3.141592653589793" xyz="1.35 0.3 1.006" />
    </joint>
    <link name="panda_top_link0">
        <visual>
            <geometry>
                <mesh filename="package://franka_description/meshes/visual/link0.dae" />
            </geometry>
        </visual>
        <collision>
            <!---->
            <origin rpy="0 1.5707963267948966 0" xyz="-0.075 0 0.06" />
            <geometry>
                <cylinder length="0.03" radius="0.06999999999999999" />
            </geometry>
        </collision>
        <collision>
            <!--base-->
            <origin rpy="0 0 0" xyz="-0.06 0 0.05" />
            <geometry>
                <box size="0.22 0.19 0.11" />
            </geometry>
        </collision>
        <collision>
            <!--base+front-->
            <origin rpy="0 0 0" xyz="0.02 0 0.03" />
            <geometry>
                <cylinder length="0.06" radius="0.06999999999999999" />
            </geometry>
        </collision>
        <collision>
            <!--base+cable-->
            <origin rpy="0 0 0" xyz="-0.09 -0.08 0.05" />
            <geometry>
                <box size="0.16 0.165 0.11" />
            </geometry>
        </collision>
        <collision>
            <!---->
            <origin rpy="0 0 0" xyz="-0.06 0 0.06" />
            <geometry>
                <sphere radius="0.06999999999999999" />
            </geometry>
        </collision>
        <collision>
            <!---->
            <origin rpy="0 0 0" xyz="-0.09 0 0.06" />
            <geometry>
                <sphere radius="0.06999999999999999" />
            </geometry>
        </collision>
        <inertial>
            <mass value="0.1" />
            <origin xyz="0 0 0" rpy="0 0 0" />
            <inertia ixx="0.03" iyy="0.03" izz="0.03" ixy="0.0" ixz="0.0" iyz="0.0" />
        </inertial>
    </link>
    <link name="panda_top_link1">
        <visual>
            <geometry>
                <mesh filename="package://franka_description/meshes/visual/link1.dae" />
            </geometry>
        </visual>
        <collision>
            <!---->
            <origin rpy="0 0 0" xyz="0 0 -0.1915" />
            <geometry>
                <cylinder length="0.2830" radius="0.06999999999999999" />
            </geometry>
        </collision>
        <collision>
            <!---->
            <origin rpy="0 0 0" xyz="0 0 -0.333" />
            <geometry>
                <sphere radius="0.06999999999999999" />
            </geometry>
        </collision>
        <collision>
            <!---->
            <origin rpy="0 0 0" xyz="0 0 -0.05" />
            <geometry>
                <sphere radius="0.06999999999999999" />
            </geometry>
        </collision>
        <collision>
            <!---->
            <origin rpy="0.5235987755982988 0 0" xyz="0 -0.05 -0.05" />
            <geometry>
                <cylinder length="0.12" radius="0.065" />
            </geometry>
        </collision>
        <inertial>
            <mass value="0.1" />
            <origin xyz="0 0 0" rpy="0 0 0" />
            <inertia ixx="0.03" iyy="0.03" izz="0.03" ixy="0.0" ixz="0.0" iyz="0.0" />
        </inertial>
    </link>
    <link name="panda_top_link1_augmented" />
    <joint name="panda_top_joint1_augmented" type="fixed">
        <origin rpy="-0.00650097874689066 0 0" xyz="-0.000171539356569936 0 0" />
        <parent link="panda_top_link0" />
        <child link="panda_top_link1_augmented" />
    </joint>
    <joint name="panda_top_joint1" type="revolute">
        <safety_controller k_position="100.0" k_velocity="40.0" soft_lower_limit="-2.8973" soft_upper_limit="2.8973" />
        <origin rpy="0 0 0.00119525002639617" xyz="0 0 0.3335915517835744" />
        <parent link="panda_top_link1_augmented" />
        <child link="panda_top_link1" />
        <axis xyz="0 0 1" />
        <limit effort="87" lower="-2.8973" upper="2.8973" velocity="2.1750" />
    </joint>
    <link name="panda_top_link2">
        <visual>
            <geometry>
                <mesh filename="package://franka_description/meshes/visual/link2.dae" />
            </geometry>
        </visual>
        <collision>
            <!---->
            <origin rpy="2.1816615649929116 0 0" xyz="0 -0.05 0.05" />
            <geometry>
                <cylinder length="0.12" radius="0.065" />
            </geometry>
        </collision>
        <collision>
            <!---->
            <origin rpy="0 0 0" xyz="0 0 0" />
            <geometry>
                <cylinder length="0.12" radius="0.06999999999999999" />
            </geometry>
        </collision>
        <collision>
            <!---->
            <origin rpy="0 0 0" xyz="0 0 -0.08" />
            <geometry>
                <sphere radius="0.06999999999999999" />
            </geometry>
        </collision>
        <collision>
            <!---->
            <origin rpy="0 0 0" xyz="0 0 0.08" />
            <geometry>
                <sphere radius="0.06999999999999999" />
            </geometry>
        </collision>
        <inertial>
            <mass value="0.1" />
            <origin xyz="0 0 0" rpy="0 0 0" />
            <inertia ixx="0.03" iyy="0.03" izz="0.03" ixy="0.0" ixz="0.0" iyz="0.0" />
        </inertial>
    </link>
    <link name="panda_top_link2_augmented" />
    <joint name="panda_top_joint2_augmented" type="fixed">
        <origin rpy="-1.5691279732231482 0 0" xyz="-0.000330274824097498 0 0" />
        <parent link="panda_top_link1" />
        <child link="panda_top_link2_augmented" />
    </joint>
    <joint name="panda_top_joint2" type="revolute">
        <safety_controller k_position="100.0" k_velocity="40.0" soft_lower_limit="-1.7628" soft_upper_limit="1.7628" />
        <origin rpy="0 0 7.10962210595555e-05" xyz="0 0 -0.000124214443868683" />
        <parent link="panda_top_link2_augmented" />
        <child link="panda_top_link2" />
        <axis xyz="0 0 1" />
        <limit effort="87" lower="-1.7628" upper="1.7628" velocity="2.1750" />
    </joint>
    <link name="panda_top_link3">
        <visual>
            <geometry>
                <mesh filename="package://franka_description/meshes/visual/link3.dae" />
            </geometry>
        </visual>
        <collision>
            <!--link3 body-->
            <origin rpy="0 0 0" xyz="0 0 -0.145" />
            <geometry>
                <cylinder length="0.15" radius="0.06999999999999999" />
            </geometry>
        </collision>
        <collision>
            <!---->
            <origin rpy="0 0 0" xyz="0 0 -0.22" />
            <geometry>
                <sphere radius="0.06999999999999999" />
            </geometry>
        </collision>
        <collision>
            <!---->
            <origin rpy="0 0 0" xyz="0 0 -0.07" />
            <geometry>
                <sphere radius="0.06999999999999999" />
            </geometry>
        </collision>
        <inertial>
            <mass value="0.1" />
            <origin xyz="0 0 0" rpy="0 0 0" />
            <inertia ixx="0.03" iyy="0.03" izz="0.03" ixy="0.0" ixz="0.0" iyz="0.0" />
        </inertial>
    </link>
    <link name="panda_top_link3_augmented" />
    <joint name="panda_top_joint3_augmented" type="fixed">
        <origin rpy="1.5689143489379758 0 0" xyz="-0.00027921463294522 0 0" />
        <parent link="panda_top_link2" />
        <child link="panda_top_link3_augmented" />
    </joint>
    <joint name="panda_top_joint3" type="revolute">
        <safety_controller k_position="100.0" k_velocity="40.0" soft_lower_limit="-2.8973" soft_upper_limit="2.8973" />
        <origin rpy="0 0 0.00203760570771006" xyz="0 0 0.3153160084577578" />
        <parent link="panda_top_link3_augmented" />
        <child link="panda_top_link3" />
        <axis xyz="0 0 1" />
        <limit effort="87" lower="-2.8973" upper="2.8973" velocity="2.1750" />
    </joint>
    <link name="panda_top_link4">
        <visual>
            <geometry>
                <mesh filename="package://franka_description/meshes/visual/link4.dae" />
            </geometry>
        </visual>
        <collision>
            <!--link4 body-->
            <origin rpy="0 0 0" xyz="0 0 0" />
            <geometry>
                <cylinder length="0.12" radius="0.06999999999999999" />
            </geometry>
        </collision>
        <collision>
            <!---->
            <origin rpy="0 0 0" xyz="0 0 0.06" />
            <geometry>
                <sphere radius="0.06999999999999999" />
            </geometry>
        </collision>
        <collision>
            <!---->
            <origin rpy="0 0 0" xyz="-0.01 0.01 0.07" />
            <geometry>
                <cylinder length="0.02" radius="0.06999999999999999" />
            </geometry>
        </collision>
        <collision>
            <!---->
            <origin rpy="0 0 0" xyz="0.01 -0.01 -0.07" />
            <geometry>
                <cylinder length="0.02" radius="0.06999999999999999" />
            </geometry>
        </collision>
        <collision>
            <!---->
            <origin rpy="0 0 0" xyz="0 0 -0.06" />
            <geometry>
                <sphere radius="0.06999999999999999" />
            </geometry>
        </collision>
        <inertial>
            <mass value="0.1" />
            <origin xyz="0 0 0" rpy="0 0 0" />
            <inertia ixx="0.03" iyy="0.03" izz="0.03" ixy="0.0" ixz="0.0" iyz="0.0" />
        </inertial>
    </link>
    <link name="panda_top_link4_augmented" />
    <joint name="panda_top_joint4_augmented" type="fixed">
        <origin rpy="1.5709645232724807 0 0" xyz="0.08214475202799297 0 0" />
        <parent link="panda_top_link3" />
        <child link="panda_top_link4_augmented" />
    </joint>
    <joint name="panda_top_joint4" type="revolute">
        <safety_controller k_position="100.0" k_velocity="40.0" soft_lower_limit="-3.0718" soft_upper_limit="-0.0698" />
        <origin rpy="0 0 -0.00513318787489872" xyz="0 0 0.000891508331427601" />
        <parent link="panda_top_link4_augmented" />
        <child link="panda_top_link4" />
        <axis xyz="0 0 1" />
        <limit effort="87" lower="-3.0718" upper="-0.0698" velocity="2.1750" />
    </joint>
    <link name="panda_top_link5">
        <visual>
            <geometry>
                <mesh filename="package://franka_description/meshes/visual/link5.dae" />
            </geometry>
        </visual>
        <collision>
            <!---->
            <origin rpy="0 0 0" xyz="0 0 -0.26" />
            <geometry>
                <cylinder length="0.1" radius="0.065" />
            </geometry>
        </collision>
        <collision>
            <!--almost link 4-->
            <origin rpy="0 0 0" xyz="0 0 -0.32" />
            <geometry>
                <sphere radius="0.065" />
            </geometry>
        </collision>
        <collision>
            <!---->
            <origin rpy="0 0 0" xyz="0 0 -0.22" />
            <geometry>
                <sphere radius="0.065" />
            </geometry>
        </collision>
        <collision>
            <!--link5 long body part-->
            <origin rpy="-0.13962634015954636 0 0" xyz="0 0.08 -0.12" />
            <geometry>
                <cylinder length="0.17" radius="0.04" />
            </geometry>
        </collision>
        <collision>
            <!--curve part-->
            <origin rpy="0 0 0" xyz="0 0.085 0" />
            <geometry>
                <sphere radius="0.065" />
            </geometry>
        </collision>
        <collision>
            <!---->
            <origin rpy="0 0 0" xyz="0 0.05 -0.19" />
            <geometry>
                <sphere radius="0.055" />
            </geometry>
        </collision>
        <inertial>
            <mass value="0.1" />
            <origin xyz="0 0 0" rpy="0 0 0" />
            <inertia ixx="0.03" iyy="0.03" izz="0.03" ixy="0.0" ixz="0.0" iyz="0.0" />
        </inertial>
    </link>
    <link name="panda_top_link5_augmented" />
    <joint name="panda_top_joint5_augmented" type="fixed">
        <origin rpy="-1.572468559921347 0 0" xyz="-0.08230918289814036 0 0" />
        <parent link="panda_top_link4" />
        <child link="panda_top_link5_augmented" />
    </joint>
    <joint name="panda_top_joint5" type="revolute">
        <safety_controller k_position="100.0" k_velocity="40.0" soft_lower_limit="-2.8973" soft_upper_limit="2.8973" />
        <origin rpy="0 0 0.00445732420517835" xyz="0 0 0.38336488148130254" />
        <parent link="panda_top_link5_augmented" />
        <child link="panda_top_link5" />
        <axis xyz="0 0 1" />
        <limit effort="12" lower="-2.8973" upper="2.8973" velocity="2.6100" />
    </joint>
    <link name="panda_top_link6">
        <visual>
            <geometry>
                <mesh filename="package://franka_description/meshes/visual/link6.dae" />
            </geometry>
        </visual>
        <collision>
            <!---->
            <origin rpy="0 0 0" xyz="0 0 -0.03" />
            <geometry>
                <cylinder length="0.08" radius="0.065" />
            </geometry>
        </collision>
        <collision>
            <!---->
            <origin rpy="0 1.5707963267948966 0" xyz="0.02 0 0.01" />
            <geometry>
                <cylinder length="0.07" radius="0.065" />
            </geometry>
        </collision>
        <collision>
            <!--curve part-->
            <origin rpy="0 0 0" xyz="0 0 0.01" />
            <geometry>
                <sphere radius="0.065" />
            </geometry>
        </collision>
        <collision>
            <!--link6and5 connection part-->
            <origin rpy="0 0 0" xyz="0 0 -0.08" />
            <geometry>
                <sphere radius="0.055999999999999994" />
            </geometry>
        </collision>
        <inertial>
            <mass value="0.1" />
            <origin xyz="0 0 0" rpy="0 0 0" />
            <inertia ixx="0.03" iyy="0.03" izz="0.03" ixy="0.0" ixz="0.0" iyz="0.0" />
        </inertial>
    </link>
    <link name="panda_top_link6_augmented" />
    <joint name="panda_top_joint6_augmented" type="fixed">
        <origin rpy="1.5672355577794053 0 0" xyz="-0.000244350284995939 0 0" />
        <parent link="panda_top_link5" />
        <child link="panda_top_link6_augmented" />
    </joint>
    <joint name="panda_top_joint6" type="revolute">
        <safety_controller k_position="100.0" k_velocity="40.0" soft_lower_limit="-0.0175" soft_upper_limit="3.7525" />
        <origin rpy="0 0 0.000118913154576129" xyz="0 0 -0.000209543585115151" />
        <parent link="panda_top_link6_augmented" />
        <child link="panda_top_link6" />
        <axis xyz="0 0 1" />
        <limit effort="12" lower="-0.0175" upper="3.7525" velocity="2.6100" />
        <!-- <limit effort="12" lower="0.75" upper="3.7525" velocity="2.6100"/> -->
    </joint>
    <link name="panda_top_link7">
        <visual>
            <geometry>
                <mesh filename="package://franka_description/meshes/visual/link7.dae" />
            </geometry>
        </visual>
        <collision>
            <!--link7's body-->
            <origin rpy="0 0 0" xyz="0 0 0.01" />
            <geometry>
                <cylinder length="0.14" radius="0.055" />
            </geometry>
        </collision>
        <collision>
            <!--link7and8 connection part-->
            <origin rpy="0 0 0" xyz="0 0 0.08" />
            <geometry>
                <sphere radius="0.05" />
            </geometry>
        </collision>
        <collision>
            <!--button part-->
            <origin rpy="0 0 0" xyz="0 0 -0.06" />
            <geometry>
                <sphere radius="0.055" />
            </geometry>
        </collision>
        <inertial>
            <mass value="0.1" />
            <origin xyz="0 0 0" rpy="0 0 0" />
            <inertia ixx="0.03" iyy="0.03" izz="0.03" ixy="0.0" ixz="0.0" iyz="0.0" />
        </inertial>
    </link>
    <link name="panda_top_link7_augmented" />
    <joint name="panda_top_joint7_augmented" type="fixed">
        <origin rpy="1.5713989088526439 0 0" xyz="0.08751580746100276 0 0" />
        <parent link="panda_top_link6" />
        <child link="panda_top_link7_augmented" />
    </joint>
    <joint name="panda_top_joint7" type="revolute">
        <safety_controller k_position="100.0" k_velocity="40.0" soft_lower_limit="-2.8973" soft_upper_limit="2.8973" />
        <origin rpy="0 0 -0.0155483388661319" xyz="0 0 4.41640702632187e-05" />
        <parent link="panda_top_link7_augmented" />
        <child link="panda_top_link7" />
        <axis xyz="0 0 1" />
        <limit effort="12" lower="-2.8973" upper="2.8973" velocity="2.6100" />
    </joint>
    <link name="panda_top_link8">
        <collision>
            <!--button part-->
            <origin rpy="0 0 0.7853981633974483" xyz="0.04 0.04 -0.03" />
            <geometry>
                <box size="0.07100000000000001 0.07100000000000001 0.021" />
            </geometry>
        </collision>
        <collision>
            <!--rotate part-->
            <origin rpy="0 0 0" xyz="0 0 -0.028" />
            <geometry>
                <cylinder length="0.05" radius="0.051000000000000004" />
            </geometry>
        </collision>
        <inertial>
            <mass value="0.1" />
            <origin xyz="0 0 0" rpy="0 0 0" />
            <inertia ixx="0.03" iyy="0.03" izz="0.03" ixy="0.0" ixz="0.0" iyz="0.0" />
        </inertial>
    </link>
    <joint name="panda_top_joint8" type="fixed">
        <origin rpy="0 0 0" xyz="0 0 0.107" />
        <parent link="panda_top_link7" />
        <child link="panda_top_link8" />
    </joint>
    <joint name="panda_top_hand_joint" type="fixed">
        <parent link="panda_top_link8" />
        <child link="panda_top_hand" />
        <origin rpy="0 0 -0.7853981633974483" xyz="0 0 0" />
    </joint>
    <link name="panda_top_hand">
        <visual>
            <origin rpy="-1.57 0 -1.57" xyz="0 0 0" />
            <geometry>
                <mesh filename="package://assembly_env_description/meshes/gripper2_base.stl" scale="0.001 0.001 0.001" />
            </geometry>
            <material name="white">
                <color rgba="0.9 0.9 0.9 0.75" />
            </material>
        </visual>
        <collision>
            <origin rpy="0 0 0" xyz="0.017 0 0.029" />
            <geometry>
                <box size="0.125 0.21 0.06" />
            </geometry>
        </collision>
        <inertial>
            <mass value="0.55" />
            <inertia ixx="0.0014362" ixy="0.000013" ixz="-0.0000278" iyy="0.00077" iyz="-0.0000000" izz="0.001039" />
            <origin xyz="0 0 0" rpy="0 0 0" />
        </inertial>
    </link>
    <joint name="panda_top_finger_right_joint" type="prismatic">
        <parent link="panda_top_hand" />
        <child link="panda_top_finger_right_link" />
        <origin rpy="0 0 0" xyz="0 0.009 +0.0590" />
        <axis xyz="0 +1 0" />
        <limit effort="1000000" lower="-0.1" upper="0.15" velocity="1000000" />
    </joint>
    <link name="panda_top_finger_right_link">
        <visual>
            <origin rpy="-1.57 0 -1.57" xyz="0 0 0" />
            <geometry>
                <mesh filename="package://assembly_env_description/meshes/gripper2_tip.stl" scale="0.001 0.001 0.001" />
            </geometry>
            <material name="gray">
                <color rgba="0.25 0.3 0.35 0.75" />
            </material>
        </visual>
        <collision>
            <origin rpy="0 0 0" xyz="0 0 0.01" />
            <geometry>
                <box size="0.08 0.0185 0.035" />
            </geometry>
        </collision>
        <inertial>
            <mass value="0.1" />
            <origin xyz="0 0 0" rpy="0 0 0" />
            <inertia ixx="0.03" iyy="0.03" izz="0.03" ixy="0.0" ixz="0.0" iyz="0.0" />
        </inertial>
    </link>
    <joint name="panda_top_finger_left_joint" type="prismatic">
        <parent link="panda_top_hand" />
        <child link="panda_top_finger_left_link" />
        <origin rpy="0 0 0" xyz="0 -0.009 +0.0590" />
        <axis xyz="0 -1 0" />
        <limit effort="1000000" lower="-0.1" upper="0.15" velocity="1000000" />
    </joint>
    <link name="panda_top_finger_left_link">
        <visual>
            <origin rpy="-1.57 0 -1.57" xyz="0 0 0" />
            <geometry>
                <mesh filename="package://assembly_env_description/meshes/gripper2_tip.stl" scale="0.001 0.001 0.001" />
            </geometry>
            <material name="gray">
                <color rgba="0.25 0.3 0.35 0.75" />
            </material>
        </visual>
        <collision>
            <origin rpy="0 0 0" xyz="0 0 0.01" />
            <geometry>
                <box size="0.08 0.0185 0.035" />
            </geometry>
        </collision>
        <inertial>
            <mass value="0.1" />
            <origin xyz="0 0 0" rpy="0 0 0" />
            <inertia ixx="0.03" iyy="0.03" izz="0.03" ixy="0.0" ixz="0.0" iyz="0.0" />
        </inertial>
    </link>
    <!-- <xacro:hand ns="panda_top" rpy="0 0 ${-pi/4}" connected_to="panda_top_link8" safety_distance="0.0"/> -->
    <transmission name="trans_panda_left_joint1">
        <type>transmission_interface/SimpleTransmission</type>
        <joint name="panda_left_joint1">
            <hardwareInterface>hardware_interface/EffortJointInterface</hardwareInterface>
        </joint>
        <actuator name="panda_left_joint1_motor">
            <hardwareInterface>hardware_interface/EffortJointInterface</hardwareInterface>
            <mechanicalReduction>1</mechanicalReduction>
        </actuator>
    </transmission>
    <transmission name="trans_panda_left_joint2">
        <type>transmission_interface/SimpleTransmission</type>
        <joint name="panda_left_joint2">
            <hardwareInterface>hardware_interface/EffortJointInterface</hardwareInterface>
        </joint>
        <actuator name="panda_left_joint2_motor">
            <hardwareInterface>hardware_interface/EffortJointInterface</hardwareInterface>
            <mechanicalReduction>1</mechanicalReduction>
        </actuator>
    </transmission>
    <transmission name="trans_panda_left_joint3">
        <type>transmission_interface/SimpleTransmission</type>
        <joint name="panda_left_joint3">
            <hardwareInterface>hardware_interface/EffortJointInterface</hardwareInterface>
        </joint>
        <actuator name="panda_left_joint3_motor">
            <hardwareInterface>hardware_interface/EffortJointInterface</hardwareInterface>
            <mechanicalReduction>1</mechanicalReduction>
        </actuator>
    </transmission>
    <transmission name="trans_panda_left_joint4">
        <type>transmission_interface/SimpleTransmission</type>
        <joint name="panda_left_joint4">
            <hardwareInterface>hardware_interface/EffortJointInterface</hardwareInterface>
        </joint>
        <actuator name="panda_left_joint4_motor">
            <hardwareInterface>hardware_interface/EffortJointInterface</hardwareInterface>
            <mechanicalReduction>1</mechanicalReduction>
        </actuator>
    </transmission>
    <transmission name="trans_panda_left_joint5">
        <type>transmission_interface/SimpleTransmission</type>
        <joint name="panda_left_joint5">
            <hardwareInterface>hardware_interface/EffortJointInterface</hardwareInterface>
        </joint>
        <actuator name="panda_left_joint5_motor">
            <hardwareInterface>hardware_interface/EffortJointInterface</hardwareInterface>
            <mechanicalReduction>1</mechanicalReduction>
        </actuator>
    </transmission>
    <transmission name="trans_panda_left_joint6">
        <type>transmission_interface/SimpleTransmission</type>
        <joint name="panda_left_joint6">
            <hardwareInterface>hardware_interface/EffortJointInterface</hardwareInterface>
        </joint>
        <actuator name="panda_left_joint6_motor">
            <hardwareInterface>hardware_interface/EffortJointInterface</hardwareInterface>
            <mechanicalReduction>1</mechanicalReduction>
        </actuator>
    </transmission>
    <transmission name="trans_panda_left_joint7">
        <type>transmission_interface/SimpleTransmission</type>
        <joint name="panda_left_joint7">
            <hardwareInterface>hardware_interface/EffortJointInterface</hardwareInterface>
        </joint>
        <actuator name="panda_left_joint7_motor">
            <hardwareInterface>hardware_interface/EffortJointInterface</hardwareInterface>
            <mechanicalReduction>1</mechanicalReduction>
        </actuator>
    </transmission>
    <transmission name="trans_panda_left_finger_joint1">
        <type>transmission_interface/SimpleTransmission</type>
        <joint name="panda_left_finger_joint1">
            <hardwareInterface>hardware_interface/EffortJointInterface</hardwareInterface>
        </joint>
        <actuator name="panda_left_finger_joint1_motor">
            <hardwareInterface>hardware_interface/EffortJointInterface</hardwareInterface>
            <mechanicalReduction>1</mechanicalReduction>
        </actuator>
    </transmission>
    <transmission name="trans_panda_left_finger_joint2">
        <type>transmission_interface/SimpleTransmission</type>
        <joint name="panda_left_finger_joint2">
            <hardwareInterface>hardware_interface/EffortJointInterface</hardwareInterface>
        </joint>
        <actuator name="panda_left_finger_joint2_motor">
            <hardwareInterface>hardware_interface/EffortJointInterface</hardwareInterface>
            <mechanicalReduction>1</mechanicalReduction>
        </actuator>
    </transmission>
    <transmission name="trans_panda_right_joint1">
        <type>transmission_interface/SimpleTransmission</type>
        <joint name="panda_right_joint1">
            <hardwareInterface>hardware_interface/EffortJointInterface</hardwareInterface>
        </joint>
        <actuator name="panda_right_joint1_motor">
            <hardwareInterface>hardware_interface/EffortJointInterface</hardwareInterface>
            <mechanicalReduction>1</mechanicalReduction>
        </actuator>
    </transmission>
    <transmission name="trans_panda_right_joint2">
        <type>transmission_interface/SimpleTransmission</type>
        <joint name="panda_right_joint2">
            <hardwareInterface>hardware_interface/EffortJointInterface</hardwareInterface>
        </joint>
        <actuator name="panda_right_joint2_motor">
            <hardwareInterface>hardware_interface/EffortJointInterface</hardwareInterface>
            <mechanicalReduction>1</mechanicalReduction>
        </actuator>
    </transmission>
    <transmission name="trans_panda_right_joint3">
        <type>transmission_interface/SimpleTransmission</type>
        <joint name="panda_right_joint3">
            <hardwareInterface>hardware_interface/EffortJointInterface</hardwareInterface>
        </joint>
        <actuator name="panda_right_joint3_motor">
            <hardwareInterface>hardware_interface/EffortJointInterface</hardwareInterface>
            <mechanicalReduction>1</mechanicalReduction>
        </actuator>
    </transmission>
    <transmission name="trans_panda_right_joint4">
        <type>transmission_interface/SimpleTransmission</type>
        <joint name="panda_right_joint4">
            <hardwareInterface>hardware_interface/EffortJointInterface</hardwareInterface>
        </joint>
        <actuator name="panda_right_joint4_motor">
            <hardwareInterface>hardware_interface/EffortJointInterface</hardwareInterface>
            <mechanicalReduction>1</mechanicalReduction>
        </actuator>
    </transmission>
    <transmission name="trans_panda_right_joint5">
        <type>transmission_interface/SimpleTransmission</type>
        <joint name="panda_right_joint5">
            <hardwareInterface>hardware_interface/EffortJointInterface</hardwareInterface>
        </joint>
        <actuator name="panda_right_joint5_motor">
            <hardwareInterface>hardware_interface/EffortJointInterface</hardwareInterface>
            <mechanicalReduction>1</mechanicalReduction>
        </actuator>
    </transmission>
    <transmission name="trans_panda_right_joint6">
        <type>transmission_interface/SimpleTransmission</type>
        <joint name="panda_right_joint6">
            <hardwareInterface>hardware_interface/EffortJointInterface</hardwareInterface>
        </joint>
        <actuator name="panda_right_joint6_motor">
            <hardwareInterface>hardware_interface/EffortJointInterface</hardwareInterface>
            <mechanicalReduction>1</mechanicalReduction>
        </actuator>
    </transmission>
    <transmission name="trans_panda_right_joint7">
        <type>transmission_interface/SimpleTransmission</type>
        <joint name="panda_right_joint7">
            <hardwareInterface>hardware_interface/EffortJointInterface</hardwareInterface>
        </joint>
        <actuator name="panda_right_joint7_motor">
            <hardwareInterface>hardware_interface/EffortJointInterface</hardwareInterface>
            <mechanicalReduction>1</mechanicalReduction>
        </actuator>
    </transmission>
    <transmission name="trans_panda_right_finger_right_joint">
        <type>transmission_interface/SimpleTransmission</type>
        <joint name="panda_right_finger_right_joint">
            <hardwareInterface>hardware_interface/EffortJointInterface</hardwareInterface>
        </joint>
        <actuator name="panda_right_finger_right_joint_motor">
            <hardwareInterface>hardware_interface/EffortJointInterface</hardwareInterface>
            <mechanicalReduction>1</mechanicalReduction>
        </actuator>
    </transmission>
    <transmission name="trans_panda_right_finger_left_joint">
        <type>transmission_interface/SimpleTransmission</type>
        <joint name="panda_right_finger_left_joint">
            <hardwareInterface>hardware_interface/EffortJointInterface</hardwareInterface>
        </joint>
        <actuator name="panda_right_finger_left_joint_motor">
            <hardwareInterface>hardware_interface/EffortJointInterface</hardwareInterface>
            <mechanicalReduction>1</mechanicalReduction>
        </actuator>
    </transmission>
    <transmission name="trans_panda_top_joint1">
        <type>transmission_interface/SimpleTransmission</type>
        <joint name="panda_top_joint1">
            <hardwareInterface>hardware_interface/EffortJointInterface</hardwareInterface>
        </joint>
        <actuator name="panda_top_joint1_motor">
            <hardwareInterface>hardware_interface/EffortJointInterface</hardwareInterface>
            <mechanicalReduction>1</mechanicalReduction>
        </actuator>
    </transmission>
    <transmission name="trans_panda_top_joint2">
        <type>transmission_interface/SimpleTransmission</type>
        <joint name="panda_top_joint2">
            <hardwareInterface>hardware_interface/EffortJointInterface</hardwareInterface>
        </joint>
        <actuator name="panda_top_joint2_motor">
            <hardwareInterface>hardware_interface/EffortJointInterface</hardwareInterface>
            <mechanicalReduction>1</mechanicalReduction>
        </actuator>
    </transmission>
    <transmission name="trans_panda_top_joint3">
        <type>transmission_interface/SimpleTransmission</type>
        <joint name="panda_top_joint3">
            <hardwareInterface>hardware_interface/EffortJointInterface</hardwareInterface>
        </joint>
        <actuator name="panda_top_joint3_motor">
            <hardwareInterface>hardware_interface/EffortJointInterface</hardwareInterface>
            <mechanicalReduction>1</mechanicalReduction>
        </actuator>
    </transmission>
    <transmission name="trans_panda_top_joint4">
        <type>transmission_interface/SimpleTransmission</type>
        <joint name="panda_top_joint4">
            <hardwareInterface>hardware_interface/EffortJointInterface</hardwareInterface>
        </joint>
        <actuator name="panda_top_joint4_motor">
            <hardwareInterface>hardware_interface/EffortJointInterface</hardwareInterface>
            <mechanicalReduction>1</mechanicalReduction>
        </actuator>
    </transmission>
    <transmission name="trans_panda_top_joint5">
        <type>transmission_interface/SimpleTransmission</type>
        <joint name="panda_top_joint5">
            <hardwareInterface>hardware_interface/EffortJointInterface</hardwareInterface>
        </joint>
        <actuator name="panda_top_joint5_motor">
            <hardwareInterface>hardware_interface/EffortJointInterface</hardwareInterface>
            <mechanicalReduction>1</mechanicalReduction>
        </actuator>
    </transmission>
    <transmission name="trans_panda_top_joint6">
        <type>transmission_interface/SimpleTransmission</type>
        <joint name="panda_top_joint6">
            <hardwareInterface>hardware_interface/EffortJointInterface</hardwareInterface>
        </joint>
        <actuator name="panda_top_joint6_motor">
            <hardwareInterface>hardware_interface/EffortJointInterface</hardwareInterface>
            <mechanicalReduction>1</mechanicalReduction>
        </actuator>
    </transmission>
    <transmission name="trans_panda_top_joint7">
        <type>transmission_interface/SimpleTransmission</type>
        <joint name="panda_top_joint7">
            <hardwareInterface>hardware_interface/EffortJointInterface</hardwareInterface>
        </joint>
        <actuator name="panda_top_joint7_motor">
            <hardwareInterface>hardware_interface/EffortJointInterface</hardwareInterface>
            <mechanicalReduction>1</mechanicalReduction>
        </actuator>
    </transmission>
    <transmission name="trans_panda_top_finger_right_joint">
        <type>transmission_interface/SimpleTransmission</type>
        <joint name="panda_top_finger_right_joint">
            <hardwareInterface>hardware_interface/EffortJointInterface</hardwareInterface>
        </joint>
        <actuator name="panda_top_finger_right_joint_motor">
            <hardwareInterface>hardware_interface/EffortJointInterface</hardwareInterface>
            <mechanicalReduction>1</mechanicalReduction>
        </actuator>
    </transmission>
    <transmission name="trans_panda_top_finger_left_joint">
        <type>transmission_interface/SimpleTransmission</type>
        <joint name="panda_top_finger_left_joint">
            <hardwareInterface>hardware_interface/EffortJointInterface</hardwareInterface>
        </joint>
        <actuator name="panda_top_finger_left_joint_motor">
            <hardwareInterface>hardware_interface/EffortJointInterface</hardwareInterface>
            <mechanicalReduction>1</mechanicalReduction>
        </actuator>
    </transmission>
    <gazebo>
        <plugin name="gazebo_ros_control">
            <robotNamespace>/</robotNamespace>
        </plugin>
    </gazebo>
</robot>

